Workbook

Sheet Feuille 1
A1: Nom du Modérateur | B1: Jour 12 (Archivé) | C1: Jour 13 (Archivé) | D1: Jour 14 (Archivé) | E1: Jour 15 (04/10) | F1: Jour 16 (05/10) | G1: Jour 17 (06/10) | H1: Jour 18 (07/10) | I1: Jour 19 (08/10) | J1: Jour 20 (09/10) | K1: Jour 21 (10/10) | L1: Jour 22 (11/10) | M1: Jour 23 (12/10) | N1: Jour 24 (13/10) | O1: Jour 25 (14/10) | P1: Jour 26 (15/10) | Q1: Jour 27 (16/10) | R1: Jour 28 (17/10) | S1: Jour 29 (18/10) | T1: Jour 30 (19/10) | U1: Total Pas là (J15-J16) | V1: Total Abs. justifiée | W1: Total Active un peu | X1: Total Active beaucoup | Y1: Taux d'assiduité | Z1: Score Global | AA1: Grade | AB1: Tendance | AC1: Rôles / Remarques
A2: lenasticot | B2: Pas là | C2: Pas là | D2: Pas là | E2: Pas là | F2: Pas là | U2: =COUNTIF($E2:$F2, "Pas là") -> 2 | V2: =COUNTIF($E2:$F2, "Absence justifiée") -> 0 | W2: =COUNTIF($E2:$F2, "Active un peu") -> 0 | X2: =COUNTIF($E2:$F2, "Active beaucoup") -> 0 | Y2: =IF((W2+X2+U2)=0, 0, (W2+X2)/(W2+X2+U2)) -> 0 | Z2: =(X2*3)+(W2*1)-(U2*1) -> -2 | AA2: =IF(Z2>=5, "👑 Top Modo", IF(Z2>=3, "⭐ Modo Actif", IF(Z2>=0, "🔎 En observation", "⚠️ Danger fantôme"))) -> ⚠️ Danger fantôme | AB2: =IFERROR(__xludf.DUMMYFUNCTION("IF(AND(E2=""Pas là"", F2=""Pas là""), ""―"", SPARKLINE({IF(E2=""Active beaucoup"",3,IF(E2=""Active un peu"",2,IF(E2=""Absence justifiée"",1,0))),IF(F2=""Active beaucoup"",3,IF(F2=""Active un peu"",2,IF(F2=""Absence justifiée"",1,0)))}, {""charttype"",""co"&"lumn"";""color"",IF(Z2>=5,""#10B981"",IF(Z2>=3,""#3B82F6"",IF(Z2>=0,""#F59E0B"",""#EF4444"")));""ymin"",0;""ymax"",3}))"),"―") -> ― | AC2: =IFERROR(__xludf.DUMMYFUNCTION("AI(""Remplis une valeur appropriée pour cette cellule en fonction du contexte de la table"")"),"Inactif") -> Inactif
A3: Sako76_ | B3: Pas là | C3: Active un peu | D3: Pas là | E3: Active un peu | F3: Active beaucoup | U3: =COUNTIF($E3:$F3, "Pas là") -> 0 | V3: =COUNTIF($E3:$F3, "Absence justifiée") -> 0 | W3: =COUNTIF($E3:$F3, "Active un peu") -> 1 | X3: =COUNTIF($E3:$F3, "Active beaucoup") -> 1 | Y3: =IF((W3+X3+U3)=0, 0, (W3+X3)/(W3+X3+U3)) -> 1 | Z3: =(X3*3)+(W3*1)-(U3*1) -> 4 | AA3: =IF(Z3>=5, "👑 Top Modo", IF(Z3>=3, "⭐ Modo Actif", IF(Z3>=0, "🔎 En observation", "⚠️ Danger fantôme"))) -> ⭐ Modo Actif | AB3: =IFERROR(__xludf.DUMMYFUNCTION("IF(AND(E3=""Pas là"", F3=""Pas là""), ""―"", SPARKLINE({IF(E3=""Active beaucoup"",3,IF(E3=""Active un peu"",2,IF(E3=""Absence justifiée"",1,0))),IF(F3=""Active beaucoup"",3,IF(F3=""Active un peu"",2,IF(F3=""Absence justifiée"",1,0)))}, {""charttype"",""co"&"lumn"";""color"",IF(Z3>=5,""#10B981"",IF(Z3>=3,""#3B82F6"",IF(Z3>=0,""#F59E0B"",""#EF4444"")));""ymin"",0;""ymax"",3}))"),"") | AC3: =IFERROR(__xludf.DUMMYFUNCTION("AI(""Remplis une valeur appropriée pour cette cellule en fonction du contexte de la table"")"),"En observation") -> En observation
A4: amandinee_22 | B4: Active beaucoup | C4: Active beaucoup | D4: Active beaucoup | E4: Active un peu | F4: Active beaucoup | U4: =COUNTIF($E4:$F4, "Pas là") -> 0 | V4: =COUNTIF($E4:$F4, "Absence justifiée") -> 0 | W4: =COUNTIF($E4:$F4, "Active un peu") -> 1 | X4: =COUNTIF($E4:$F4, "Active beaucoup") -> 1 | Y4: =IF((W4+X4+U4)=0, 0, (W4+X4)/(W4+X4+U4)) -> 1 | Z4: =(X4*3)+(W4*1)-(U4*1) -> 4 | AA4: =IF(Z4>=5, "👑 Top Modo", IF(Z4>=3, "⭐ Modo Actif", IF(Z4>=0, "🔎 En observation", "⚠️ Danger fantôme"))) -> ⭐ Modo Actif | AB4: =IFERROR(__xludf.DUMMYFUNCTION("IF(AND(E4=""Pas là"", F4=""Pas là""), ""―"", SPARKLINE({IF(E4=""Active beaucoup"",3,IF(E4=""Active un peu"",2,IF(E4=""Absence justifiée"",1,0))),IF(F4=""Active beaucoup"",3,IF(F4=""Active un peu"",2,IF(F4=""Absence justifiée"",1,0)))}, {""charttype"",""co"&"lumn"";""color"",IF(Z4>=5,""#10B981"",IF(Z4>=3,""#3B82F6"",IF(Z4>=0,""#F59E0B"",""#EF4444"")));""ymin"",0;""ymax"",3}))"),"") | AC4: =IFERROR(__xludf.DUMMYFUNCTION("AI(""Remplis une valeur appropriée pour cette cellule en fonction du contexte de la table"")"),"Très actif") -> Très actif
A5: pnj_rizou | B5: Active un peu | C5: Active un peu | D5: Pas là | E5: Pas là | F5: Pas là | U5: =COUNTIF($E5:$F5, "Pas là") -> 2 | V5: =COUNTIF($E5:$F5, "Absence justifiée") -> 0 | W5: =COUNTIF($E5:$F5, "Active un peu") -> 0 | X5: =COUNTIF($E5:$F5, "Active beaucoup") -> 0 | Y5: =IF((W5+X5+U5)=0, 0, (W5+X5)/(W5+X5+U5)) -> 0 | Z5: =(X5*3)+(W5*1)-(U5*1) -> -2 | AA5: =IF(Z5>=5, "👑 Top Modo", IF(Z5>=3, "⭐ Modo Actif", IF(Z5>=0, "🔎 En observation", "⚠️ Danger fantôme"))) -> ⚠️ Danger fantôme | AB5: =IFERROR(__xludf.DUMMYFUNCTION("IF(AND(E5=""Pas là"", F5=""Pas là""), ""―"", SPARKLINE({IF(E5=""Active beaucoup"",3,IF(E5=""Active un peu"",2,IF(E5=""Absence justifiée"",1,0))),IF(F5=""Active beaucoup"",3,IF(F5=""Active un peu"",2,IF(F5=""Absence justifiée"",1,0)))}, {""charttype"",""co"&"lumn"";""color"",IF(Z5>=5,""#10B981"",IF(Z5>=3,""#3B82F6"",IF(Z5>=0,""#F59E0B"",""#EF4444"")));""ymin"",0;""ymax"",3}))"),"―") -> ― | AC5: =IFERROR(__xludf.DUMMYFUNCTION("AI(""Remplis une valeur appropriée pour cette cellule en fonction du contexte de la table"")"),"Peu actif") -> Peu actif
A6: bistourii69 | B6: Active beaucoup | C6: Active un peu | D6: Absence justifiée | E6: Pas là | F6: Pas là | U6: =COUNTIF($E6:$F6, "Pas là") -> 2 | V6: =COUNTIF($E6:$F6, "Absence justifiée") -> 0 | W6: =COUNTIF($E6:$F6, "Active un peu") -> 0 | X6: =COUNTIF($E6:$F6, "Active beaucoup") -> 0 | Y6: =IF((W6+X6+U6)=0, 0, (W6+X6)/(W6+X6+U6)) -> 0 | Z6: =(X6*3)+(W6*1)-(U6*1) -> -2 | AA6: =IF(Z6>=5, "👑 Top Modo", IF(Z6>=3, "⭐ Modo Actif", IF(Z6>=0, "🔎 En observation", "⚠️ Danger fantôme"))) -> ⚠️ Danger fantôme | AB6: =IFERROR(__xludf.DUMMYFUNCTION("IF(AND(E6=""Pas là"", F6=""Pas là""), ""―"", SPARKLINE({IF(E6=""Active beaucoup"",3,IF(E6=""Active un peu"",2,IF(E6=""Absence justifiée"",1,0))),IF(F6=""Active beaucoup"",3,IF(F6=""Active un peu"",2,IF(F6=""Absence justifiée"",1,0)))}, {""charttype"",""co"&"lumn"";""color"",IF(Z6>=5,""#10B981"",IF(Z6>=3,""#3B82F6"",IF(Z6>=0,""#F59E0B"",""#EF4444"")));""ymin"",0;""ymax"",3}))"),"―") -> ― | AC6: =IFERROR(__xludf.DUMMYFUNCTION("AI(""Remplis une valeur appropriée pour cette cellule en fonction du contexte de la table"")"),"En observation") -> En observation
A7: issac_45s | B7: Absence justifiée | C7: Absence justifiée | D7: Absence justifiée | E7: Pas là | F7: Pas là | U7: =COUNTIF($E7:$F7, "Pas là") -> 2 | V7: =COUNTIF($E7:$F7, "Absence justifiée") -> 0 | W7: =COUNTIF($E7:$F7, "Active un peu") -> 0 | X7: =COUNTIF($E7:$F7, "Active beaucoup") -> 0 | Y7: =IF((W7+X7+U7)=0, 0, (W7+X7)/(W7+X7+U7)) -> 0 | Z7: =(X7*3)+(W7*1)-(U7*1) -> -2 | AA7: =IF(Z7>=5, "👑 Top Modo", IF(Z7>=3, "⭐ Modo Actif", IF(Z7>=0, "🔎 En observation", "⚠️ Danger fantôme"))) -> ⚠️ Danger fantôme | AB7: =IFERROR(__xludf.DUMMYFUNCTION("IF(AND(E7=""Pas là"", F7=""Pas là""), ""―"", SPARKLINE({IF(E7=""Active beaucoup"",3,IF(E7=""Active un peu"",2,IF(E7=""Absence justifiée"",1,0))),IF(F7=""Active beaucoup"",3,IF(F7=""Active un peu"",2,IF(F7=""Absence justifiée"",1,0)))}, {""charttype"",""co"&"lumn"";""color"",IF(Z7>=5,""#10B981"",IF(Z7>=3,""#3B82F6"",IF(Z7>=0,""#F59E0B"",""#EF4444"")));""ymin"",0;""ymax"",3}))"),"―") -> ― | AC7: =IFERROR(__xludf.DUMMYFUNCTION("AI(""Remplis une valeur appropriée pour cette cellule en fonction du contexte de la table"")"),"Absence prolongée") -> Absence prolongée
A8: Vropext | B8: Pas là | C8: Pas là | D8: Pas là | E8: Pas là | F8: Pas là | U8: =COUNTIF($E8:$F8, "Pas là") -> 2 | V8: =COUNTIF($E8:$F8, "Absence justifiée") -> 0 | W8: =COUNTIF($E8:$F8, "Active un peu") -> 0 | X8: =COUNTIF($E8:$F8, "Active beaucoup") -> 0 | Y8: =IF((W8+X8+U8)=0, 0, (W8+X8)/(W8+X8+U8)) -> 0 | Z8: =(X8*3)+(W8*1)-(U8*1) -> -2 | AA8: =IF(Z8>=5, "👑 Top Modo", IF(Z8>=3, "⭐ Modo Actif", IF(Z8>=0, "🔎 En observation", "⚠️ Danger fantôme"))) -> ⚠️ Danger fantôme | AB8: =IFERROR(__xludf.DUMMYFUNCTION("IF(AND(E8=""Pas là"", F8=""Pas là""), ""―"", SPARKLINE({IF(E8=""Active beaucoup"",3,IF(E8=""Active un peu"",2,IF(E8=""Absence justifiée"",1,0))),IF(F8=""Active beaucoup"",3,IF(F8=""Active un peu"",2,IF(F8=""Absence justifiée"",1,0)))}, {""charttype"",""co"&"lumn"";""color"",IF(Z8>=5,""#10B981"",IF(Z8>=3,""#3B82F6"",IF(Z8>=0,""#F59E0B"",""#EF4444"")));""ymin"",0;""ymax"",3}))"),"―") -> ― | AC8: =IFERROR(__xludf.DUMMYFUNCTION("AI(""Remplis une valeur appropriée pour cette cellule en fonction du contexte de la table"")"),"Inactif") -> Inactif
A9: Xdayman | B9: Active beaucoup | C9: Active un peu | D9: Absence justifiée | E9: Active un peu | F9: Active beaucoup | U9: =COUNTIF($E9:$F9, "Pas là") -> 0 | V9: =COUNTIF($E9:$F9, "Absence justifiée") -> 0 | W9: =COUNTIF($E9:$F9, "Active un peu") -> 1 | X9: =COUNTIF($E9:$F9, "Active beaucoup") -> 1 | Y9: =IF((W9+X9+U9)=0, 0, (W9+X9)/(W9+X9+U9)) -> 1 | Z9: =(X9*3)+(W9*1)-(U9*1) -> 4 | AA9: =IF(Z9>=5, "👑 Top Modo", IF(Z9>=3, "⭐ Modo Actif", IF(Z9>=0, "🔎 En observation", "⚠️ Danger fantôme"))) -> ⭐ Modo Actif | AB9: =IFERROR(__xludf.DUMMYFUNCTION("IF(AND(E9=""Pas là"", F9=""Pas là""), ""―"", SPARKLINE({IF(E9=""Active beaucoup"",3,IF(E9=""Active un peu"",2,IF(E9=""Absence justifiée"",1,0))),IF(F9=""Active beaucoup"",3,IF(F9=""Active un peu"",2,IF(F9=""Absence justifiée"",1,0)))}, {""charttype"",""co"&"lumn"";""color"",IF(Z9>=5,""#10B981"",IF(Z9>=3,""#3B82F6"",IF(Z9>=0,""#F59E0B"",""#EF4444"")));""ymin"",0;""ymax"",3}))"),"") | AC9: =IFERROR(__xludf.DUMMYFUNCTION("AI(""Remplis une valeur appropriée pour cette cellule en fonction du contexte de la table"")"),"Actif") -> Actif
A10: ARCKOOOOOOOOS | B10: Active beaucoup | C10: Active beaucoup | D10: Absence justifiée | E10: Pas là | F10: Active beaucoup | U10: =COUNTIF($E10:$F10, "Pas là") -> 1 | V10: =COUNTIF($E10:$F10, "Absence justifiée") -> 0 | W10: =COUNTIF($E10:$F10, "Active un peu") -> 0 | X10: =COUNTIF($E10:$F10, "Active beaucoup") -> 1 | Y10: =IF((W10+X10+U10)=0, 0, (W10+X10)/(W10+X10+U10)) -> 0.5 | Z10: =(X10*3)+(W10*1)-(U10*1) -> 2 | AA10: =IF(Z10>=5, "👑 Top Modo", IF(Z10>=3, "⭐ Modo Actif", IF(Z10>=0, "🔎 En observation", "⚠️ Danger fantôme"))) -> 🔎 En observation | AB10: =IFERROR(__xludf.DUMMYFUNCTION("IF(AND(E10=""Pas là"", F10=""Pas là""), ""―"", SPARKLINE({IF(E10=""Active beaucoup"",3,IF(E10=""Active un peu"",2,IF(E10=""Absence justifiée"",1,0))),IF(F10=""Active beaucoup"",3,IF(F10=""Active un peu"",2,IF(F10=""Absence justifiée"",1,0)))}, {""charttyp"&"e"",""column"";""color"",IF(Z10>=5,""#10B981"",IF(Z10>=3,""#3B82F6"",IF(Z10>=0,""#F59E0B"",""#EF4444"")));""ymin"",0;""ymax"",3}))"),"") | AC10: =IFERROR(__xludf.DUMMYFUNCTION("AI(""Remplis une valeur appropriée pour cette cellule en fonction du contexte de la table"")"),"Actif") -> Actif
A11: ssbk691 | B11: Active un peu | C11: Active beaucoup | D11: Active beaucoup | E11: Active un peu | F11: Active un peu | U11: =COUNTIF($E11:$F11, "Pas là") -> 0 | V11: =COUNTIF($E11:$F11, "Absence justifiée") -> 0 | W11: =COUNTIF($E11:$F11, "Active un peu") -> 2 | X11: =COUNTIF($E11:$F11, "Active beaucoup") -> 0 | Y11: =IF((W11+X11+U11)=0, 0, (W11+X11)/(W11+X11+U11)) -> 1 | Z11: =(X11*3)+(W11*1)-(U11*1) -> 2 | AA11: =IF(Z11>=5, "👑 Top Modo", IF(Z11>=3, "⭐ Modo Actif", IF(Z11>=0, "🔎 En observation", "⚠️ Danger fantôme"))) -> 🔎 En observation | AB11: =IFERROR(__xludf.DUMMYFUNCTION("IF(AND(E11=""Pas là"", F11=""Pas là""), ""―"", SPARKLINE({IF(E11=""Active beaucoup"",3,IF(E11=""Active un peu"",2,IF(E11=""Absence justifiée"",1,0))),IF(F11=""Active beaucoup"",3,IF(F11=""Active un peu"",2,IF(F11=""Absence justifiée"",1,0)))}, {""charttyp"&"e"",""column"";""color"",IF(Z11>=5,""#10B981"",IF(Z11>=3,""#3B82F6"",IF(Z11>=0,""#F59E0B"",""#EF4444"")));""ymin"",0;""ymax"",3}))"),"") | AC11: =IFERROR(__xludf.DUMMYFUNCTION("AI(""Remplis une valeur appropriée pour cette cellule en fonction du contexte de la table"")"),"Actif") -> Actif
A12: Mwerte | B12: Active beaucoup | C12: Active beaucoup | D12: Absence justifiée | E12: Pas là | F12: Active beaucoup | U12: =COUNTIF($E12:$F12, "Pas là") -> 1 | V12: =COUNTIF($E12:$F12, "Absence justifiée") -> 0 | W12: =COUNTIF($E12:$F12, "Active un peu") -> 0 | X12: =COUNTIF($E12:$F12, "Active beaucoup") -> 1 | Y12: =IF((W12+X12+U12)=0, 0, (W12+X12)/(W12+X12+U12)) -> 0.5 | Z12: =(X12*3)+(W12*1)-(U12*1) -> 2 | AA12: =IF(Z12>=5, "👑 Top Modo", IF(Z12>=3, "⭐ Modo Actif", IF(Z12>=0, "🔎 En observation", "⚠️ Danger fantôme"))) -> 🔎 En observation | AB12: =IFERROR(__xludf.DUMMYFUNCTION("IF(AND(E12=""Pas là"", F12=""Pas là""), ""―"", SPARKLINE({IF(E12=""Active beaucoup"",3,IF(E12=""Active un peu"",2,IF(E12=""Absence justifiée"",1,0))),IF(F12=""Active beaucoup"",3,IF(F12=""Active un peu"",2,IF(F12=""Absence justifiée"",1,0)))}, {""charttyp"&"e"",""column"";""color"",IF(Z12>=5,""#10B981"",IF(Z12>=3,""#3B82F6"",IF(Z12>=0,""#F59E0B"",""#EF4444"")));""ymin"",0;""ymax"",3}))"),"") | AC12: =IFERROR(__xludf.DUMMYFUNCTION("AI(""Remplis une valeur appropriée pour cette cellule en fonction du contexte de la table"")"),"Actif") -> Actif
A13: Navidlakers | B13: Absence justifiée | C13: Pas là | D13: Pas là | E13: Pas là | F13: Pas là | U13: =COUNTIF($E13:$F13, "Pas là") -> 2 | V13: =COUNTIF($E13:$F13, "Absence justifiée") -> 0 | W13: =COUNTIF($E13:$F13, "Active un peu") -> 0 | X13: =COUNTIF($E13:$F13, "Active beaucoup") -> 0 | Y13: =IF((W13+X13+U13)=0, 0, (W13+X13)/(W13+X13+U13)) -> 0 | Z13: =(X13*3)+(W13*1)-(U13*1) -> -2 | AA13: =IF(Z13>=5, "👑 Top Modo", IF(Z13>=3, "⭐ Modo Actif", IF(Z13>=0, "🔎 En observation", "⚠️ Danger fantôme"))) -> ⚠️ Danger fantôme | AB13: =IFERROR(__xludf.DUMMYFUNCTION("IF(AND(E13=""Pas là"", F13=""Pas là""), ""―"", SPARKLINE({IF(E13=""Active beaucoup"",3,IF(E13=""Active un peu"",2,IF(E13=""Absence justifiée"",1,0))),IF(F13=""Active beaucoup"",3,IF(F13=""Active un peu"",2,IF(F13=""Absence justifiée"",1,0)))}, {""charttyp"&"e"",""column"";""color"",IF(Z13>=5,""#10B981"",IF(Z13>=3,""#3B82F6"",IF(Z13>=0,""#F59E0B"",""#EF4444"")));""ymin"",0;""ymax"",3}))"),"―") -> ― | AC13: =IFERROR(__xludf.DUMMYFUNCTION("AI(""Remplis une valeur appropriée pour cette cellule en fonction du contexte de la table"")"),"Inactif") -> Inactif
A14: wissale_brk | B14: Pas là | C14: Pas là | D14: Pas là | E14: Active beaucoup | F14: Pas là | U14: =COUNTIF($E14:$F14, "Pas là") -> 1 | V14: =COUNTIF($E14:$F14, "Absence justifiée") -> 0 | W14: =COUNTIF($E14:$F14, "Active un peu") -> 0 | X14: =COUNTIF($E14:$F14, "Active beaucoup") -> 1 | Y14: =IF((W14+X14+U14)=0, 0, (W14+X14)/(W14+X14+U14)) -> 0.5 | Z14: =(X14*3)+(W14*1)-(U14*1) -> 2 | AA14: =IF(Z14>=5, "👑 Top Modo", IF(Z14>=3, "⭐ Modo Actif", IF(Z14>=0, "🔎 En observation", "⚠️ Danger fantôme"))) -> 🔎 En observation | AB14: =IFERROR(__xludf.DUMMYFUNCTION("IF(AND(E14=""Pas là"", F14=""Pas là""), ""―"", SPARKLINE({IF(E14=""Active beaucoup"",3,IF(E14=""Active un peu"",2,IF(E14=""Absence justifiée"",1,0))),IF(F14=""Active beaucoup"",3,IF(F14=""Active un peu"",2,IF(F14=""Absence justifiée"",1,0)))}, {""charttyp"&"e"",""column"";""color"",IF(Z14>=5,""#10B981"",IF(Z14>=3,""#3B82F6"",IF(Z14>=0,""#F59E0B"",""#EF4444"")));""ymin"",0;""ymax"",3}))"),"") | AC14: =IFERROR(__xludf.DUMMYFUNCTION("AI(""Remplis une valeur appropriée pour cette cellule en fonction du contexte de la table"")"),"Peu actif") -> Peu actif
A15: zeerty667 | B15: Pas là | C15: Pas là | D15: Pas là | E15: Pas là | F15: Pas là | U15: =COUNTIF($E15:$F15, "Pas là") -> 2 | V15: =COUNTIF($E15:$F15, "Absence justifiée") -> 0 | W15: =COUNTIF($E15:$F15, "Active un peu") -> 0 | X15: =COUNTIF($E15:$F15, "Active beaucoup") -> 0 | Y15: =IF((W15+X15+U15)=0, 0, (W15+X15)/(W15+X15+U15)) -> 0 | Z15: =(X15*3)+(W15*1)-(U15*1) -> -2 | AA15: =IF(Z15>=5, "👑 Top Modo", IF(Z15>=3, "⭐ Modo Actif", IF(Z15>=0, "🔎 En observation", "⚠️ Danger fantôme"))) -> ⚠️ Danger fantôme | AB15: =IFERROR(__xludf.DUMMYFUNCTION("IF(AND(E15=""Pas là"", F15=""Pas là""), ""―"", SPARKLINE({IF(E15=""Active beaucoup"",3,IF(E15=""Active un peu"",2,IF(E15=""Absence justifiée"",1,0))),IF(F15=""Active beaucoup"",3,IF(F15=""Active un peu"",2,IF(F15=""Absence justifiée"",1,0)))}, {""charttyp"&"e"",""column"";""color"",IF(Z15>=5,""#10B981"",IF(Z15>=3,""#3B82F6"",IF(Z15>=0,""#F59E0B"",""#EF4444"")));""ymin"",0;""ymax"",3}))"),"―") -> ― | AC15: =IFERROR(__xludf.DUMMYFUNCTION("AI(""Remplis une valeur appropriée pour cette cellule en fonction du contexte de la table"")"),"Inactif") -> Inactif
A16: moonstoness__ | B16: Active beaucoup | C16: Active beaucoup | D16: Active beaucoup | E16: Active beaucoup | F16: Absence justifiée | G16: Absence justifiée | U16: =COUNTIF($E16:$F16, "Pas là") -> 0 | V16: =COUNTIF($E16:$F16, "Absence justifiée") -> 1 | W16: =COUNTIF($E16:$F16, "Active un peu") -> 0 | X16: =COUNTIF($E16:$F16, "Active beaucoup") -> 1 | Y16: =IF((W16+X16+U16)=0, 0, (W16+X16)/(W16+X16+U16)) -> 1 | Z16: =(X16*3)+(W16*1)-(U16*1) -> 3 | AA16: =IF(Z16>=5, "👑 Top Modo", IF(Z16>=3, "⭐ Modo Actif", IF(Z16>=0, "🔎 En observation", "⚠️ Danger fantôme"))) -> ⭐ Modo Actif | AB16: =IFERROR(__xludf.DUMMYFUNCTION("IF(AND(E16=""Pas là"", F16=""Pas là""), ""―"", SPARKLINE({IF(E16=""Active beaucoup"",3,IF(E16=""Active un peu"",2,IF(E16=""Absence justifiée"",1,0))),IF(F16=""Active beaucoup"",3,IF(F16=""Active un peu"",2,IF(F16=""Absence justifiée"",1,0)))}, {""charttyp"&"e"",""column"";""color"",IF(Z16>=5,""#10B981"",IF(Z16>=3,""#3B82F6"",IF(Z16>=0,""#F59E0B"",""#EF4444"")));""ymin"",0;""ymax"",3}))"),"") | AC16: =IFERROR(__xludf.DUMMYFUNCTION("AI(""Remplis une valeur appropriée pour cette cellule en fonction du contexte de la table"")"),"Très actif") -> Très actif
A17: seraly_ | B17: Active un peu | C17: Pas là | D17: Pas là | E17: Pas là | F17: Pas là | U17: =COUNTIF($E17:$F17, "Pas là") -> 2 | V17: =COUNTIF($E17:$F17, "Absence justifiée") -> 0 | W17: =COUNTIF($E17:$F17, "Active un peu") -> 0 | X17: =COUNTIF($E17:$F17, "Active beaucoup") -> 0 | Y17: =IF((W17+X17+U17)=0, 0, (W17+X17)/(W17+X17+U17)) -> 0 | Z17: =(X17*3)+(W17*1)-(U17*1) -> -2 | AA17: =IF(Z17>=5, "👑 Top Modo", IF(Z17>=3, "⭐ Modo Actif", IF(Z17>=0, "🔎 En observation", "⚠️ Danger fantôme"))) -> ⚠️ Danger fantôme | AB17: =IFERROR(__xludf.DUMMYFUNCTION("IF(AND(E17=""Pas là"", F17=""Pas là""), ""―"", SPARKLINE({IF(E17=""Active beaucoup"",3,IF(E17=""Active un peu"",2,IF(E17=""Absence justifiée"",1,0))),IF(F17=""Active beaucoup"",3,IF(F17=""Active un peu"",2,IF(F17=""Absence justifiée"",1,0)))}, {""charttyp"&"e"",""column"";""color"",IF(Z17>=5,""#10B981"",IF(Z17>=3,""#3B82F6"",IF(Z17>=0,""#F59E0B"",""#EF4444"")));""ymin"",0;""ymax"",3}))"),"―") -> ― | AC17: =IFERROR(__xludf.DUMMYFUNCTION("AI(""Remplis une valeur appropriée pour cette cellule en fonction du contexte de la table"")"),"Inactif") -> Inactif
A18: Dr_chay (Retirée - Comportement irrespectueux) | B18: - | C18: - | D18: - | E18: Active un peu | F18: Pas là | U18: =COUNTIF($E18:$F18, "Pas là") -> 1 | V18: =COUNTIF($E18:$F18, "Absence justifiée") -> 0 | W18: =COUNTIF($E18:$F18, "Active un peu") -> 1 | X18: =COUNTIF($E18:$F18, "Active beaucoup") -> 0 | Y18: =IF((W18+X18+U18)=0, 0, (W18+X18)/(W18+X18+U18)) -> 0.5 | Z18: =(X18*3)+(W18*1)-(U18*1) -> 0 | AA18: =IF(Z18>=5, "👑 Top Modo", IF(Z18>=3, "⭐ Modo Actif", IF(Z18>=0, "🔎 En observation", "⚠️ Danger fantôme"))) -> 🔎 En observation | AB18: =IFERROR(__xludf.DUMMYFUNCTION("IF(AND(E18=""Pas là"", F18=""Pas là""), ""―"", SPARKLINE({IF(E18=""Active beaucoup"",3,IF(E18=""Active un peu"",2,IF(E18=""Absence justifiée"",1,0))),IF(F18=""Active beaucoup"",3,IF(F18=""Active un peu"",2,IF(F18=""Absence justifiée"",1,0)))}, {""charttyp"&"e"",""column"";""color"",IF(Z18>=5,""#10B981"",IF(Z18>=3,""#3B82F6"",IF(Z18>=0,""#F59E0B"",""#EF4444"")));""ymin"",0;""ymax"",3}))"),"") | AC18: =IFERROR(__xludf.DUMMYFUNCTION("AI(""Remplis une valeur appropriée pour cette cellule en fonction du contexte de la table"")"),"Retirée") -> Retirée
A19: AyssAFK | B19: Active beaucoup | C19: Pas là | D19: Active beaucoup | E19: Active beaucoup | F19: Active beaucoup | U19: =COUNTIF($E19:$F19, "Pas là") -> 0 | V19: =COUNTIF($E19:$F19, "Absence justifiée") -> 0 | W19: =COUNTIF($E19:$F19, "Active un peu") -> 0 | X19: =COUNTIF($E19:$F19, "Active beaucoup") -> 2 | Y19: =IF((W19+X19+U19)=0, 0, (W19+X19)/(W19+X19+U19)) -> 1 | Z19: =(X19*3)+(W19*1)-(U19*1) -> 6 | AA19: =IF(Z19>=5, "👑 Top Modo", IF(Z19>=3, "⭐ Modo Actif", IF(Z19>=0, "🔎 En observation", "⚠️ Danger fantôme"))) -> 👑 Top Modo | AB19: =IFERROR(__xludf.DUMMYFUNCTION("IF(AND(E19=""Pas là"", F19=""Pas là""), ""―"", SPARKLINE({IF(E19=""Active beaucoup"",3,IF(E19=""Active un peu"",2,IF(E19=""Absence justifiée"",1,0))),IF(F19=""Active beaucoup"",3,IF(F19=""Active un peu"",2,IF(F19=""Absence justifiée"",1,0)))}, {""charttyp"&"e"",""column"";""color"",IF(Z19>=5,""#10B981"",IF(Z19>=3,""#3B82F6"",IF(Z19>=0,""#F59E0B"",""#EF4444"")));""ymin"",0;""ymax"",3}))"),"") | AC19: =IFERROR(__xludf.DUMMYFUNCTION("AI(""Remplis une valeur appropriée pour cette cellule en fonction du contexte de la table"")"),"Actif") -> Actif
A20: rayaaannn_ | B20: Pas là | C20: Pas là | D20: Pas là | E20: Pas là | F20: Pas là | U20: =COUNTIF($E20:$F20, "Pas là") -> 2 | V20: =COUNTIF($E20:$F20, "Absence justifiée") -> 0 | W20: =COUNTIF($E20:$F20, "Active un peu") -> 0 | X20: =COUNTIF($E20:$F20, "Active beaucoup") -> 0 | Y20: =IF((W20+X20+U20)=0, 0, (W20+X20)/(W20+X20+U20)) -> 0 | Z20: =(X20*3)+(W20*1)-(U20*1) -> -2 | AA20: =IF(Z20>=5, "👑 Top Modo", IF(Z20>=3, "⭐ Modo Actif", IF(Z20>=0, "🔎 En observation", "⚠️ Danger fantôme"))) -> ⚠️ Danger fantôme | AB20: =IFERROR(__xludf.DUMMYFUNCTION("IF(AND(E20=""Pas là"", F20=""Pas là""), ""―"", SPARKLINE({IF(E20=""Active beaucoup"",3,IF(E20=""Active un peu"",2,IF(E20=""Absence justifiée"",1,0))),IF(F20=""Active beaucoup"",3,IF(F20=""Active un peu"",2,IF(F20=""Absence justifiée"",1,0)))}, {""charttyp"&"e"",""column"";""color"",IF(Z20>=5,""#10B981"",IF(Z20>=3,""#3B82F6"",IF(Z20>=0,""#F59E0B"",""#EF4444"")));""ymin"",0;""ymax"",3}))"),"―") -> ― | AC20: =IFERROR(__xludf.DUMMYFUNCTION("AI(""Remplis une valeur appropriée pour cette cellule en fonction du contexte de la table"")"),"Inactif") -> Inactif
A21: camilliaa_s | B21: Absence justifiée | C21: Absence justifiée | D21: Absence justifiée | E21: Pas là | F21: Pas là | U21: =COUNTIF($E21:$F21, "Pas là") -> 2 | V21: =COUNTIF($E21:$F21, "Absence justifiée") -> 0 | W21: =COUNTIF($E21:$F21, "Active un peu") -> 0 | X21: =COUNTIF($E21:$F21, "Active beaucoup") -> 0 | Y21: =IF((W21+X21+U21)=0, 0, (W21+X21)/(W21+X21+U21)) -> 0 | Z21: =(X21*3)+(W21*1)-(U21*1) -> -2 | AA21: =IF(Z21>=5, "👑 Top Modo", IF(Z21>=3, "⭐ Modo Actif", IF(Z21>=0, "🔎 En observation", "⚠️ Danger fantôme"))) -> ⚠️ Danger fantôme | AB21: =IFERROR(__xludf.DUMMYFUNCTION("IF(AND(E21=""Pas là"", F21=""Pas là""), ""―"", SPARKLINE({IF(E21=""Active beaucoup"",3,IF(E21=""Active un peu"",2,IF(E21=""Absence justifiée"",1,0))),IF(F21=""Active beaucoup"",3,IF(F21=""Active un peu"",2,IF(F21=""Absence justifiée"",1,0)))}, {""charttyp"&"e"",""column"";""color"",IF(Z21>=5,""#10B981"",IF(Z21>=3,""#3B82F6"",IF(Z21>=0,""#F59E0B"",""#EF4444"")));""ymin"",0;""ymax"",3}))"),"―") -> ― | AC21: =IFERROR(__xludf.DUMMYFUNCTION("AI(""Remplis une valeur appropriée pour cette cellule en fonction du contexte de la table"")"),"Absence justifiée") -> Absence justifiée
A22: Su_wii | B22: Pas là | C22: Active un peu | D22: Active un peu | E22: Active un peu | F22: Active beaucoup | U22: =COUNTIF($E22:$F22, "Pas là") -> 0 | V22: =COUNTIF($E22:$F22, "Absence justifiée") -> 0 | W22: =COUNTIF($E22:$F22, "Active un peu") -> 1 | X22: =COUNTIF($E22:$F22, "Active beaucoup") -> 1 | Y22: =IF((W22+X22+U22)=0, 0, (W22+X22)/(W22+X22+U22)) -> 1 | Z22: =(X22*3)+(W22*1)-(U22*1) -> 4 | AA22: =IF(Z22>=5, "👑 Top Modo", IF(Z22>=3, "⭐ Modo Actif", IF(Z22>=0, "🔎 En observation", "⚠️ Danger fantôme"))) -> ⭐ Modo Actif | AB22: =IFERROR(__xludf.DUMMYFUNCTION("IF(AND(E22=""Pas là"", F22=""Pas là""), ""―"", SPARKLINE({IF(E22=""Active beaucoup"",3,IF(E22=""Active un peu"",2,IF(E22=""Absence justifiée"",1,0))),IF(F22=""Active beaucoup"",3,IF(F22=""Active un peu"",2,IF(F22=""Absence justifiée"",1,0)))}, {""charttyp"&"e"",""column"";""color"",IF(Z22>=5,""#10B981"",IF(Z22>=3,""#3B82F6"",IF(Z22>=0,""#F59E0B"",""#EF4444"")));""ymin"",0;""ymax"",3}))"),"") | AC22: =IFERROR(__xludf.DUMMYFUNCTION("AI(""Remplis une valeur appropriée pour cette cellule en fonction du contexte de la table"")"),"Peu actif") -> Peu actif
A23: Laucss | B23: Pas là | C23: Absence justifiée | D23: Pas là | E23: Pas là | F23: Pas là | U23: =COUNTIF($E23:$F23, "Pas là") -> 2 | V23: =COUNTIF($E23:$F23, "Absence justifiée") -> 0 | W23: =COUNTIF($E23:$F23, "Active un peu") -> 0 | X23: =COUNTIF($E23:$F23, "Active beaucoup") -> 0 | Y23: =IF((W23+X23+U23)=0, 0, (W23+X23)/(W23+X23+U23)) -> 0 | Z23: =(X23*3)+(W23*1)-(U23*1) -> -2 | AA23: =IF(Z23>=5, "👑 Top Modo", IF(Z23>=3, "⭐ Modo Actif", IF(Z23>=0, "🔎 En observation", "⚠️ Danger fantôme"))) -> ⚠️ Danger fantôme | AB23: =IFERROR(__xludf.DUMMYFUNCTION("IF(AND(E23=""Pas là"", F23=""Pas là""), ""―"", SPARKLINE({IF(E23=""Active beaucoup"",3,IF(E23=""Active un peu"",2,IF(E23=""Absence justifiée"",1,0))),IF(F23=""Active beaucoup"",3,IF(F23=""Active un peu"",2,IF(F23=""Absence justifiée"",1,0)))}, {""charttyp"&"e"",""column"";""color"",IF(Z23>=5,""#10B981"",IF(Z23>=3,""#3B82F6"",IF(Z23>=0,""#F59E0B"",""#EF4444"")));""ymin"",0;""ymax"",3}))"),"―") -> ― | AC23: =IFERROR(__xludf.DUMMYFUNCTION("AI(""Remplis une valeur appropriée pour cette cellule en fonction du contexte de la table"")"),"Inactif") -> Inactif
A24: jawad_4k | B24: Active beaucoup | C24: Active beaucoup | D24: Active beaucoup | E24: Active beaucoup | F24: Active beaucoup | U24: =COUNTIF($E24:$F24, "Pas là") -> 0 | V24: =COUNTIF($E24:$F24, "Absence justifiée") -> 0 | W24: =COUNTIF($E24:$F24, "Active un peu") -> 0 | X24: =COUNTIF($E24:$F24, "Active beaucoup") -> 2 | Y24: =IF((W24+X24+U24)=0, 0, (W24+X24)/(W24+X24+U24)) -> 1 | Z24: =(X24*3)+(W24*1)-(U24*1) -> 6 | AA24: =IF(Z24>=5, "👑 Top Modo", IF(Z24>=3, "⭐ Modo Actif", IF(Z24>=0, "🔎 En observation", "⚠️ Danger fantôme"))) -> 👑 Top Modo | AB24: =IFERROR(__xludf.DUMMYFUNCTION("IF(AND(E24=""Pas là"", F24=""Pas là""), ""―"", SPARKLINE({IF(E24=""Active beaucoup"",3,IF(E24=""Active un peu"",2,IF(E24=""Absence justifiée"",1,0))),IF(F24=""Active beaucoup"",3,IF(F24=""Active un peu"",2,IF(F24=""Absence justifiée"",1,0)))}, {""charttyp"&"e"",""column"";""color"",IF(Z24>=5,""#10B981"",IF(Z24>=3,""#3B82F6"",IF(Z24>=0,""#F59E0B"",""#EF4444"")));""ymin"",0;""ymax"",3}))"),"") | AC24: =IFERROR(__xludf.DUMMYFUNCTION("AI(""Remplis une valeur appropriée pour cette cellule en fonction du contexte de la table"")"),"Actif") -> Actif
A25: uf_th3_dreamzz | B25: Active un peu | C25: Active beaucoup | D25: Active un peu | E25: Active beaucoup | F25: Active beaucoup | U25: =COUNTIF($E25:$F25, "Pas là") -> 0 | V25: =COUNTIF($E25:$F25, "Absence justifiée") -> 0 | W25: =COUNTIF($E25:$F25, "Active un peu") -> 0 | X25: =COUNTIF($E25:$F25, "Active beaucoup") -> 2 | Y25: =IF((W25+X25+U25)=0, 0, (W25+X25)/(W25+X25+U25)) -> 1 | Z25: =(X25*3)+(W25*1)-(U25*1) -> 6 | AA25: =IF(Z25>=5, "👑 Top Modo", IF(Z25>=3, "⭐ Modo Actif", IF(Z25>=0, "🔎 En observation", "⚠️ Danger fantôme"))) -> 👑 Top Modo | AB25: =IFERROR(__xludf.DUMMYFUNCTION("IF(AND(E25=""Pas là"", F25=""Pas là""), ""―"", SPARKLINE({IF(E25=""Active beaucoup"",3,IF(E25=""Active un peu"",2,IF(E25=""Absence justifiée"",1,0))),IF(F25=""Active beaucoup"",3,IF(F25=""Active un peu"",2,IF(F25=""Absence justifiée"",1,0)))}, {""charttyp"&"e"",""column"";""color"",IF(Z25>=5,""#10B981"",IF(Z25>=3,""#3B82F6"",IF(Z25>=0,""#F59E0B"",""#EF4444"")));""ymin"",0;""ymax"",3}))"),"") | AC25: =IFERROR(__xludf.DUMMYFUNCTION("AI(""Remplis une valeur appropriée pour cette cellule en fonction du contexte de la table"")"),"Actif") -> Actif
A26: nini_nesss | B26: Active beaucoup | C26: Absence justifiée | D26: Absence justifiée | E26: Active beaucoup | F26: Active beaucoup | U26: =COUNTIF($E26:$F26, "Pas là") -> 0 | V26: =COUNTIF($E26:$F26, "Absence justifiée") -> 0 | W26: =COUNTIF($E26:$F26, "Active un peu") -> 0 | X26: =COUNTIF($E26:$F26, "Active beaucoup") -> 2 | Y26: =IF((W26+X26+U26)=0, 0, (W26+X26)/(W26+X26+U26)) -> 1 | Z26: =(X26*3)+(W26*1)-(U26*1) -> 6 | AA26: =IF(Z26>=5, "👑 Top Modo", IF(Z26>=3, "⭐ Modo Actif", IF(Z26>=0, "🔎 En observation", "⚠️ Danger fantôme"))) -> 👑 Top Modo | AB26: =IFERROR(__xludf.DUMMYFUNCTION("IF(AND(E26=""Pas là"", F26=""Pas là""), ""―"", SPARKLINE({IF(E26=""Active beaucoup"",3,IF(E26=""Active un peu"",2,IF(E26=""Absence justifiée"",1,0))),IF(F26=""Active beaucoup"",3,IF(F26=""Active un peu"",2,IF(F26=""Absence justifiée"",1,0)))}, {""charttyp"&"e"",""column"";""color"",IF(Z26>=5,""#10B981"",IF(Z26>=3,""#3B82F6"",IF(Z26>=0,""#F59E0B"",""#EF4444"")));""ymin"",0;""ymax"",3}))"),"") | AC26: =IFERROR(__xludf.DUMMYFUNCTION("AI(""Remplis une valeur appropriée pour cette cellule en fonction du contexte de la table"")"),"Actif") -> Actif
A27: imRqin | E27: Active beaucoup | F27: Active beaucoup | U27: =COUNTIF($E27:$F27, "Pas là") -> 0 | V27: =COUNTIF($E27:$F27, "Absence justifiée") -> 0 | W27: =COUNTIF($E27:$F27, "Active un peu") -> 0 | X27: =COUNTIF($E27:$F27, "Active beaucoup") -> 2 | Y27: =IF((W27+X27+U27)=0, 0, (W27+X27)/(W27+X27+U27)) -> 1 | Z27: =(X27*3)+(W27*1)-(U27*1) -> 6 | AA27: =IF(Z27>=5, "👑 Top Modo", IF(Z27>=3, "⭐ Modo Actif", IF(Z27>=0, "🔎 En observation", "⚠️ Danger fantôme"))) -> 👑 Top Modo | AB27: =IFERROR(__xludf.DUMMYFUNCTION("IF(AND(E27=""Pas là"", F27=""Pas là""), ""―"", SPARKLINE({IF(E27=""Active beaucoup"",3,IF(E27=""Active un peu"",2,IF(E27=""Absence justifiée"",1,0))),IF(F27=""Active beaucoup"",3,IF(F27=""Active un peu"",2,IF(F27=""Absence justifiée"",1,0)))}, {""charttyp"&"e"",""column"";""color"",IF(Z27>=5,""#10B981"",IF(Z27>=3,""#3B82F6"",IF(Z27>=0,""#F59E0B"",""#EF4444"")));""ymin"",0;""ymax"",3}))"),"") | AC27: =IFERROR(__xludf.DUMMYFUNCTION("AI(""Remplis une valeur appropriée pour cette cellule en fonction du contexte de la table"")"),"Actif") -> Actif
A28: naxoo_of | E28: Active beaucoup | F28: Active un peu | U28: =COUNTIF($E28:$F28, "Pas là") -> 0 | V28: =COUNTIF($E28:$F28, "Absence justifiée") -> 0 | W28: =COUNTIF($E28:$F28, "Active un peu") -> 1 | X28: =COUNTIF($E28:$F28, "Active beaucoup") -> 1 | Y28: =IF((W28+X28+U28)=0, 0, (W28+X28)/(W28+X28+U28)) -> 1 | Z28: =(X28*3)+(W28*1)-(U28*1) -> 4 | AA28: =IF(Z28>=5, "👑 Top Modo", IF(Z28>=3, "⭐ Modo Actif", IF(Z28>=0, "🔎 En observation", "⚠️ Danger fantôme"))) -> ⭐ Modo Actif | AB28: =IFERROR(__xludf.DUMMYFUNCTION("IF(AND(E28=""Pas là"", F28=""Pas là""), ""―"", SPARKLINE({IF(E28=""Active beaucoup"",3,IF(E28=""Active un peu"",2,IF(E28=""Absence justifiée"",1,0))),IF(F28=""Active beaucoup"",3,IF(F28=""Active un peu"",2,IF(F28=""Absence justifiée"",1,0)))}, {""charttyp"&"e"",""column"";""color"",IF(Z28>=5,""#10B981"",IF(Z28>=3,""#3B82F6"",IF(Z28>=0,""#F59E0B"",""#EF4444"")));""ymin"",0;""ymax"",3}))"),"") | AC28: =IFERROR(__xludf.DUMMYFUNCTION("AI(""Remplis une valeur appropriée pour cette cellule en fonction du contexte de la table"")"),"Actif") -> Actif
A29: eren835_ | E29: Active un peu | F29: Active beaucoup | U29: =COUNTIF($E29:$F29, "Pas là") -> 0 | V29: =COUNTIF($E29:$F29, "Absence justifiée") -> 0 | W29: =COUNTIF($E29:$F29, "Active un peu") -> 1 | X29: =COUNTIF($E29:$F29, "Active beaucoup") -> 1 | Y29: =IF((W29+X29+U29)=0, 0, (W29+X29)/(W29+X29+U29)) -> 1 | Z29: =(X29*3)+(W29*1)-(U29*1) -> 4 | AA29: =IF(Z29>=5, "👑 Top Modo", IF(Z29>=3, "⭐ Modo Actif", IF(Z29>=0, "🔎 En observation", "⚠️ Danger fantôme"))) -> ⭐ Modo Actif | AB29: =IFERROR(__xludf.DUMMYFUNCTION("IF(AND(E29=""Pas là"", F29=""Pas là""), ""―"", SPARKLINE({IF(E29=""Active beaucoup"",3,IF(E29=""Active un peu"",2,IF(E29=""Absence justifiée"",1,0))),IF(F29=""Active beaucoup"",3,IF(F29=""Active un peu"",2,IF(F29=""Absence justifiée"",1,0)))}, {""charttyp"&"e"",""column"";""color"",IF(Z29>=5,""#10B981"",IF(Z29>=3,""#3B82F6"",IF(Z29>=0,""#F59E0B"",""#EF4444"")));""ymin"",0;""ymax"",3}))"),"") | AC29: =IFERROR(__xludf.DUMMYFUNCTION("AI(""Remplis une valeur appropriée pour cette cellule en fonction du contexte de la table"")"),"En observation") -> En observation
A30: spideradl | E30: Pas là | F30: Active beaucoup | I30: Absence justifiée | J30: Absence justifiée | K30: Absence justifiée | L30: Absence justifiée | U30: =COUNTIF($E30:$F30, "Pas là") -> 1 | V30: =COUNTIF($E30:$F30, "Absence justifiée") -> 0 | W30: =COUNTIF($E30:$F30, "Active un peu") -> 0 | X30: =COUNTIF($E30:$F30, "Active beaucoup") -> 1 | Y30: =IF((W30+X30+U30)=0, 0, (W30+X30)/(W30+X30+U30)) -> 0.5 | Z30: =(X30*3)+(W30*1)-(U30*1) -> 2 | AA30: =IF(Z30>=5, "👑 Top Modo", IF(Z30>=3, "⭐ Modo Actif", IF(Z30>=0, "🔎 En observation", "⚠️ Danger fantôme"))) -> 🔎 En observation | AB30: =IFERROR(__xludf.DUMMYFUNCTION("IF(AND(E30=""Pas là"", F30=""Pas là""), ""―"", SPARKLINE({IF(E30=""Active beaucoup"",3,IF(E30=""Active un peu"",2,IF(E30=""Absence justifiée"",1,0))),IF(F30=""Active beaucoup"",3,IF(F30=""Active un peu"",2,IF(F30=""Absence justifiée"",1,0)))}, {""charttyp"&"e"",""column"";""color"",IF(Z30>=5,""#10B981"",IF(Z30>=3,""#3B82F6"",IF(Z30>=0,""#F59E0B"",""#EF4444"")));""ymin"",0;""ymax"",3}))"),"") | AC30: =IFERROR(__xludf.DUMMYFUNCTION("AI(""Remplis une valeur appropriée pour cette cellule en fonction du contexte de la table"")"),"En observation") -> En observation
A31: enzoot_ | E31: Active un peu | F31: Active un peu | U31: =COUNTIF($E31:$F31, "Pas là") -> 0 | V31: =COUNTIF($E31:$F31, "Absence justifiée") -> 0 | W31: =COUNTIF($E31:$F31, "Active un peu") -> 2 | X31: =COUNTIF($E31:$F31, "Active beaucoup") -> 0 | Y31: =IF((W31+X31+U31)=0, 0, (W31+X31)/(W31+X31+U31)) -> 1 | Z31: =(X31*3)+(W31*1)-(U31*1) -> 2 | AA31: =IF(Z31>=5, "👑 Top Modo", IF(Z31>=3, "⭐ Modo Actif", IF(Z31>=0, "🔎 En observation", "⚠️ Danger fantôme"))) -> 🔎 En observation | AB31: =IFERROR(__xludf.DUMMYFUNCTION("IF(AND(E31=""Pas là"", F31=""Pas là""), ""―"", SPARKLINE({IF(E31=""Active beaucoup"",3,IF(E31=""Active un peu"",2,IF(E31=""Absence justifiée"",1,0))),IF(F31=""Active beaucoup"",3,IF(F31=""Active un peu"",2,IF(F31=""Absence justifiée"",1,0)))}, {""charttyp"&"e"",""column"";""color"",IF(Z31>=5,""#10B981"",IF(Z31>=3,""#3B82F6"",IF(Z31>=0,""#F59E0B"",""#EF4444"")));""ymin"",0;""ymax"",3}))"),"") | AC31: =IFERROR(__xludf.DUMMYFUNCTION("AI(""Remplis une valeur appropriée pour cette cellule en fonction du contexte de la table"")"),"En observation") -> En observation
A32: TbKyronOxf | E32: Active un peu | F32: Pas là | U32: =COUNTIF($E32:$F32, "Pas là") -> 1 | V32: =COUNTIF($E32:$F32, "Absence justifiée") -> 0 | W32: =COUNTIF($E32:$F32, "Active un peu") -> 1 | X32: =COUNTIF($E32:$F32, "Active beaucoup") -> 0 | Y32: =IF((W32+X32+U32)=0, 0, (W32+X32)/(W32+X32+U32)) -> 0.5 | Z32: =(X32*3)+(W32*1)-(U32*1) -> 0 | AA32: =IF(Z32>=5, "👑 Top Modo", IF(Z32>=3, "⭐ Modo Actif", IF(Z32>=0, "🔎 En observation", "⚠️ Danger fantôme"))) -> 🔎 En observation | AB32: =IFERROR(__xludf.DUMMYFUNCTION("IF(AND(E32=""Pas là"", F32=""Pas là""), ""―"", SPARKLINE({IF(E32=""Active beaucoup"",3,IF(E32=""Active un peu"",2,IF(E32=""Absence justifiée"",1,0))),IF(F32=""Active beaucoup"",3,IF(F32=""Active un peu"",2,IF(F32=""Absence justifiée"",1,0)))}, {""charttyp"&"e"",""column"";""color"",IF(Z32>=5,""#10B981"",IF(Z32>=3,""#3B82F6"",IF(Z32>=0,""#F59E0B"",""#EF4444"")));""ymin"",0;""ymax"",3}))"),"") | AC32: =IFERROR(__xludf.DUMMYFUNCTION("AI(""Remplis une valeur appropriée pour cette cellule en fonction du contexte de la table"")"),"En observation") -> En observation
A33: juuliiee__ | E33: Pas là | F33: Active un peu | U33: =COUNTIF($E33:$F33, "Pas là") -> 1 | V33: =COUNTIF($E33:$F33, "Absence justifiée") -> 0 | W33: =COUNTIF($E33:$F33, "Active un peu") -> 1 | X33: =COUNTIF($E33:$F33, "Active beaucoup") -> 0 | Y33: =IF((W33+X33+U33)=0, 0, (W33+X33)/(W33+X33+U33)) -> 0.5 | Z33: =(X33*3)+(W33*1)-(U33*1) -> 0 | AA33: =IF(Z33>=5, "👑 Top Modo", IF(Z33>=3, "⭐ Modo Actif", IF(Z33>=0, "🔎 En observation", "⚠️ Danger fantôme"))) -> 🔎 En observation | AB33: =IFERROR(__xludf.DUMMYFUNCTION("IF(AND(E33=""Pas là"", F33=""Pas là""), ""―"", SPARKLINE({IF(E33=""Active beaucoup"",3,IF(E33=""Active un peu"",2,IF(E33=""Absence justifiée"",1,0))),IF(F33=""Active beaucoup"",3,IF(F33=""Active un peu"",2,IF(F33=""Absence justifiée"",1,0)))}, {""charttyp"&"e"",""column"";""color"",IF(Z33>=5,""#10B981"",IF(Z33>=3,""#3B82F6"",IF(Z33>=0,""#F59E0B"",""#EF4444"")));""ymin"",0;""ymax"",3}))"),"") | AC33: =IFERROR(__xludf.DUMMYFUNCTION("AI(""Remplis une valeur appropriée pour cette cellule en fonction du contexte de la table"")"),"Peu actif") -> Peu actif
A34: Lizukiii | E34: Pas là | F34: Active un peu | U34: =COUNTIF($E34:$F34, "Pas là") -> 1 | V34: =COUNTIF($E34:$F34, "Absence justifiée") -> 0 | W34: =COUNTIF($E34:$F34, "Active un peu") -> 1 | X34: =COUNTIF($E34:$F34, "Active beaucoup") -> 0 | Y34: =IF((W34+X34+U34)=0, 0, (W34+X34)/(W34+X34+U34)) -> 0.5 | Z34: =(X34*3)+(W34*1)-(U34*1) -> 0 | AA34: =IF(Z34>=5, "👑 Top Modo", IF(Z34>=3, "⭐ Modo Actif", IF(Z34>=0, "🔎 En observation", "⚠️ Danger fantôme"))) -> 🔎 En observation | AB34: =IFERROR(__xludf.DUMMYFUNCTION("IF(AND(E34=""Pas là"", F34=""Pas là""), ""―"", SPARKLINE({IF(E34=""Active beaucoup"",3,IF(E34=""Active un peu"",2,IF(E34=""Absence justifiée"",1,0))),IF(F34=""Active beaucoup"",3,IF(F34=""Active un peu"",2,IF(F34=""Absence justifiée"",1,0)))}, {""charttyp"&"e"",""column"";""color"",IF(Z34>=5,""#10B981"",IF(Z34>=3,""#3B82F6"",IF(Z34>=0,""#F59E0B"",""#EF4444"")));""ymin"",0;""ymax"",3}))"),"") | AC34: =IFERROR(__xludf.DUMMYFUNCTION("AI(""Remplis une valeur appropriée pour cette cellule en fonction du contexte de la table"")"),"Inactif") -> Inactif
A35: Phenicia10 | E35: Active un peu | F35: Absence justifiée | G35: Absence justifiée | U35: =COUNTIF($E35:$F35, "Pas là") -> 0 | V35: =COUNTIF($E35:$F35, "Absence justifiée") -> 1 | W35: =COUNTIF($E35:$F35, "Active un peu") -> 1 | X35: =COUNTIF($E35:$F35, "Active beaucoup") -> 0 | Y35: =IF((W35+X35+U35)=0, 0, (W35+X35)/(W35+X35+U35)) -> 1 | Z35: =(X35*3)+(W35*1)-(U35*1) -> 1 | AA35: =IF(Z35>=5, "👑 Top Modo", IF(Z35>=3, "⭐ Modo Actif", IF(Z35>=0, "🔎 En observation", "⚠️ Danger fantôme"))) -> 🔎 En observation | AB35: =IFERROR(__xludf.DUMMYFUNCTION("IF(AND(E35=""Pas là"", F35=""Pas là""), ""―"", SPARKLINE({IF(E35=""Active beaucoup"",3,IF(E35=""Active un peu"",2,IF(E35=""Absence justifiée"",1,0))),IF(F35=""Active beaucoup"",3,IF(F35=""Active un peu"",2,IF(F35=""Absence justifiée"",1,0)))}, {""charttyp"&"e"",""column"";""color"",IF(Z35>=5,""#10B981"",IF(Z35>=3,""#3B82F6"",IF(Z35>=0,""#F59E0B"",""#EF4444"")));""ymin"",0;""ymax"",3}))"),"") | AC35: =IFERROR(__xludf.DUMMYFUNCTION("AI(""Remplis une valeur appropriée pour cette cellule en fonction du contexte de la table"")"),"Inactif") -> Inactif
A36: alizee05_ | E36: Active un peu | F36: Pas là | U36: =COUNTIF($E36:$F36, "Pas là") -> 1 | V36: =COUNTIF($E36:$F36, "Absence justifiée") -> 0 | W36: =COUNTIF($E36:$F36, "Active un peu") -> 1 | X36: =COUNTIF($E36:$F36, "Active beaucoup") -> 0 | Y36: =IF((W36+X36+U36)=0, 0, (W36+X36)/(W36+X36+U36)) -> 0.5 | Z36: =(X36*3)+(W36*1)-(U36*1) -> 0 | AA36: =IF(Z36>=5, "👑 Top Modo", IF(Z36>=3, "⭐ Modo Actif", IF(Z36>=0, "🔎 En observation", "⚠️ Danger fantôme"))) -> 🔎 En observation | AB36: =IFERROR(__xludf.DUMMYFUNCTION("IF(AND(E36=""Pas là"", F36=""Pas là""), ""―"", SPARKLINE({IF(E36=""Active beaucoup"",3,IF(E36=""Active un peu"",2,IF(E36=""Absence justifiée"",1,0))),IF(F36=""Active beaucoup"",3,IF(F36=""Active un peu"",2,IF(F36=""Absence justifiée"",1,0)))}, {""charttyp"&"e"",""column"";""color"",IF(Z36>=5,""#10B981"",IF(Z36>=3,""#3B82F6"",IF(Z36>=0,""#F59E0B"",""#EF4444"")));""ymin"",0;""ymax"",3}))"),"") | AC36: =IFERROR(__xludf.DUMMYFUNCTION("AI(""Remplis une valeur appropriée pour cette cellule en fonction du contexte de la table"")"),"Inactif") -> Inactif
A37: Nico_la | E37: Pas là | F37: Active un peu | U37: =COUNTIF($E37:$F37, "Pas là") -> 1 | V37: =COUNTIF($E37:$F37, "Absence justifiée") -> 0 | W37: =COUNTIF($E37:$F37, "Active un peu") -> 1 | X37: =COUNTIF($E37:$F37, "Active beaucoup") -> 0 | Y37: =IF((W37+X37+U37)=0, 0, (W37+X37)/(W37+X37+U37)) -> 0.5 | Z37: =(X37*3)+(W37*1)-(U37*1) -> 0 | AA37: =IF(Z37>=5, "👑 Top Modo", IF(Z37>=3, "⭐ Modo Actif", IF(Z37>=0, "🔎 En observation", "⚠️ Danger fantôme"))) -> 🔎 En observation | AB37: =IFERROR(__xludf.DUMMYFUNCTION("IF(AND(E37=""Pas là"", F37=""Pas là""), ""―"", SPARKLINE({IF(E37=""Active beaucoup"",3,IF(E37=""Active un peu"",2,IF(E37=""Absence justifiée"",1,0))),IF(F37=""Active beaucoup"",3,IF(F37=""Active un peu"",2,IF(F37=""Absence justifiée"",1,0)))}, {""charttyp"&"e"",""column"";""color"",IF(Z37>=5,""#10B981"",IF(Z37>=3,""#3B82F6"",IF(Z37>=0,""#F59E0B"",""#EF4444"")));""ymin"",0;""ymax"",3}))"),"") | AC37: =IFERROR(__xludf.DUMMYFUNCTION("AI(""Remplis une valeur appropriée pour cette cellule en fonction du contexte de la table"")"),"Peu actif") -> Peu actif
A38: samol1t0 | E38: Pas là | F38: Active un peu | U38: =COUNTIF($E38:$F38, "Pas là") -> 1 | V38: =COUNTIF($E38:$F38, "Absence justifiée") -> 0 | W38: =COUNTIF($E38:$F38, "Active un peu") -> 1 | X38: =COUNTIF($E38:$F38, "Active beaucoup") -> 0 | Y38: =IF((W38+X38+U38)=0, 0, (W38+X38)/(W38+X38+U38)) -> 0.5 | Z38: =(X38*3)+(W38*1)-(U38*1) -> 0 | AA38: =IF(Z38>=5, "👑 Top Modo", IF(Z38>=3, "⭐ Modo Actif", IF(Z38>=0, "🔎 En observation", "⚠️ Danger fantôme"))) -> 🔎 En observation | AB38: =IFERROR(__xludf.DUMMYFUNCTION("IF(AND(E38=""Pas là"", F38=""Pas là""), ""―"", SPARKLINE({IF(E38=""Active beaucoup"",3,IF(E38=""Active un peu"",2,IF(E38=""Absence justifiée"",1,0))),IF(F38=""Active beaucoup"",3,IF(F38=""Active un peu"",2,IF(F38=""Absence justifiée"",1,0)))}, {""charttyp"&"e"",""column"";""color"",IF(Z38>=5,""#10B981"",IF(Z38>=3,""#3B82F6"",IF(Z38>=0,""#F59E0B"",""#EF4444"")));""ymin"",0;""ymax"",3}))"),"") | AC38: =IFERROR(__xludf.DUMMYFUNCTION("AI(""Remplis une valeur appropriée pour cette cellule en fonction du contexte de la table"")"),"Inactif") -> Inactif
A39: LeBob_tv | B39: Absence justifiée | C39: Absence justifiée | D39: Absence justifiée | E39: Pas là | F39: Active un peu | U39: =COUNTIF($E39:$F39, "Pas là") -> 1 | V39: =COUNTIF($E39:$F39, "Absence justifiée") -> 0 | W39: =COUNTIF($E39:$F39, "Active un peu") -> 1 | X39: =COUNTIF($E39:$F39, "Active beaucoup") -> 0 | Y39: =IF((W39+X39+U39)=0, 0, (W39+X39)/(W39+X39+U39)) -> 0.5 | Z39: =(X39*3)+(W39*1)-(U39*1) -> 0 | AA39: =IF(Z39>=5, "👑 Top Modo", IF(Z39>=3, "⭐ Modo Actif", IF(Z39>=0, "🔎 En observation", "⚠️ Danger fantôme"))) -> 🔎 En observation | AB39: =IFERROR(__xludf.DUMMYFUNCTION("IF(AND(E39=""Pas là"", F39=""Pas là""), ""―"", SPARKLINE({IF(E39=""Active beaucoup"",3,IF(E39=""Active un peu"",2,IF(E39=""Absence justifiée"",1,0))),IF(F39=""Active beaucoup"",3,IF(F39=""Active un peu"",2,IF(F39=""Absence justifiée"",1,0)))}, {""charttyp"&"e"",""column"";""color"",IF(Z39>=5,""#10B981"",IF(Z39>=3,""#3B82F6"",IF(Z39>=0,""#F59E0B"",""#EF4444"")));""ymin"",0;""ymax"",3}))"),"") | AC39: =IFERROR(__xludf.DUMMYFUNCTION("AI(""Remplis une valeur appropriée pour cette cellule en fonction du contexte de la table"")"),"Peu actif") -> Peu actif
A41: Rang | B41: Modérateur | D41: Score | F41: ASSIDUITÉ MOYENNE | I41: SCORE MOYEN | L41: MODOS ACTIFS | O41: ALERTES FANTÔME | R41: EFFECTIF TOTAL
...

Sheet Cockpit Interactif
B1: 🛡️ COCKPIT DE PILOTAGE ET PERFORMANCE DES MODÉRATEURS | P1: Modérateur (Top) | Q1: Score Global | S1: Grade | T1: Effectif
B2: Suivi d'activité en temps réel • Période active J15-J16 • Analyse individuelle et collective | P2: =IFERROR(__xludf.DUMMYFUNCTION("INDEX(SORT(FILTER('Feuille 1'!A2:A39, NOT(ISNUMBER(SEARCH(""Retirée"", 'Feuille 1'!A2:A39)))), FILTER('Feuille 1'!Z2:Z39, NOT(ISNUMBER(SEARCH(""Retirée"", 'Feuille 1'!A2:A39)))), FALSE, FILTER('Feuille 1'!Y2:Y39, NOT(ISNUMBER(SEARCH(""Retirée"", 'Feuille "&"1'!A2:A39)))), FALSE), 1)"),"AyssAFK") -> AyssAFK | Q2: =IFERROR(__xludf.DUMMYFUNCTION("INDEX(SORT(FILTER('Feuille 1'!Z2:Z39, NOT(ISNUMBER(SEARCH(""Retirée"", 'Feuille 1'!A2:A39)))), FILTER('Feuille 1'!Z2:Z39, NOT(ISNUMBER(SEARCH(""Retirée"", 'Feuille 1'!A2:A39)))), FALSE, FILTER('Feuille 1'!Y2:Y39, NOT(ISNUMBER(SEARCH(""Retirée"", 'Feuille "&"1'!A2:A39)))), FALSE), 1)"),6.0) -> 6 | S2: 👑 Top Modo | T2: =COUNTIF('Feuille 1'!AA2:AA39, "👑 Top Modo") -> 5
B3: 👥 EFFECTIF TOTAL | D3: 📈 ASSIDUITÉ MOYENNE | F3: ⭐ MODOS ACTIFS | H3: ⚠️ ALERTES FANTÔME | J3: 🎯 SCORE MOYEN | L3: ⚡ ACTIONS ÉQUIPE | P3: =IFERROR(__xludf.DUMMYFUNCTION("INDEX(SORT(FILTER('Feuille 1'!A2:A39, NOT(ISNUMBER(SEARCH(""Retirée"", 'Feuille 1'!A2:A39)))), FILTER('Feuille 1'!Z2:Z39, NOT(ISNUMBER(SEARCH(""Retirée"", 'Feuille 1'!A2:A39)))), FALSE, FILTER('Feuille 1'!Y2:Y39, NOT(ISNUMBER(SEARCH(""Retirée"", 'Feuille "&"1'!A2:A39)))), FALSE), 2)"),"jawad_4k") -> jawad_4k | Q3: =IFERROR(__xludf.DUMMYFUNCTION("INDEX(SORT(FILTER('Feuille 1'!Z2:Z39, NOT(ISNUMBER(SEARCH(""Retirée"", 'Feuille 1'!A2:A39)))), FILTER('Feuille 1'!Z2:Z39, NOT(ISNUMBER(SEARCH(""Retirée"", 'Feuille 1'!A2:A39)))), FALSE, FILTER('Feuille 1'!Y2:Y39, NOT(ISNUMBER(SEARCH(""Retirée"", 'Feuille "&"1'!A2:A39)))), FALSE), 2)"),6.0) -> 6 | S3: ⭐ Modo Actif | T3: =COUNTIF('Feuille 1'!AA2:AA39, "⭐ Modo Actif") -> 7
B4: =COUNTA('Feuille 1'!A2:A39) - COUNTIF('Feuille 1'!A2:A39, "*Retirée*") -> 37 | D4: =IFERROR(__xludf.DUMMYFUNCTION("AVERAGE(FILTER('Feuille 1'!Y2:Y39, NOT(ISNUMBER(SEARCH(""Retirée"", 'Feuille 1'!A2:A39)))))"),0.5540540540540541) -> 0.55405405 | F4: =COUNTIF('Feuille 1'!AA2:AA39, "*Top Modo*") + COUNTIF('Feuille 1'!AA2:AA39, "*Modo Actif*") -> 12 | H4: =COUNTIF('Feuille 1'!AA2:AA39, "*Danger*") -> 11 | J4: =IFERROR(__xludf.DUMMYFUNCTION("AVERAGE(FILTER('Feuille 1'!Z2:Z39, NOT(ISNUMBER(SEARCH(""Retirée"", 'Feuille 1'!A2:A39)))))"),1.2972972972972974) -> 1.2972973 | L4: ='Actions Modération'!E44 -> 784 | P4: =IFERROR(__xludf.DUMMYFUNCTION("INDEX(SORT(FILTER('Feuille 1'!A2:A39, NOT(ISNUMBER(SEARCH(""Retirée"", 'Feuille 1'!A2:A39)))), FILTER('Feuille 1'!Z2:Z39, NOT(ISNUMBER(SEARCH(""Retirée"", 'Feuille 1'!A2:A39)))), FALSE, FILTER('Feuille 1'!Y2:Y39, NOT(ISNUMBER(SEARCH(""Retirée"", 'Feuille "&"1'!A2:A39)))), FALSE), 3)"),"uf_th3_dreamzz") -> uf_th3_dreamzz | Q4: =IFERROR(__xludf.DUMMYFUNCTION("INDEX(SORT(FILTER('Feuille 1'!Z2:Z39, NOT(ISNUMBER(SEARCH(""Retirée"", 'Feuille 1'!A2:A39)))), FILTER('Feuille 1'!Z2:Z39, NOT(ISNUMBER(SEARCH(""Retirée"", 'Feuille 1'!A2:A39)))), FALSE, FILTER('Feuille 1'!Y2:Y39, NOT(ISNUMBER(SEARCH(""Retirée"", 'Feuille "&"1'!A2:A39)))), FALSE), 3)"),6.0) -> 6 | S4: 🔎 En observation | T4: =COUNTIF('Feuille 1'!AA2:AA39, "🔎 En observation") - COUNTIF('Feuille 1'!A2:A39, "*Retirée*") -> 14
B5: Membres opérationnels | D5: Taux moyen (J15-J16) | F5: Top & Actifs (≥ 3 pts) | H5: À surveiller / Relancer | J5: Points actifs / modo | L5: Période active (2 jours) | P5: =IFERROR(__xludf.DUMMYFUNCTION("INDEX(SORT(FILTER('Feuille 1'!A2:A39, NOT(ISNUMBER(SEARCH(""Retirée"", 'Feuille 1'!A2:A39)))), FILTER('Feuille 1'!Z2:Z39, NOT(ISNUMBER(SEARCH(""Retirée"", 'Feuille 1'!A2:A39)))), FALSE, FILTER('Feuille 1'!Y2:Y39, NOT(ISNUMBER(SEARCH(""Retirée"", 'Feuille "&"1'!A2:A39)))), FALSE), 4)"),"nini_nesss") -> nini_nesss | Q5: =IFERROR(__xludf.DUMMYFUNCTION("INDEX(SORT(FILTER('Feuille 1'!Z2:Z39, NOT(ISNUMBER(SEARCH(""Retirée"", 'Feuille 1'!A2:A39)))), FILTER('Feuille 1'!Z2:Z39, NOT(ISNUMBER(SEARCH(""Retirée"", 'Feuille 1'!A2:A39)))), FALSE, FILTER('Feuille 1'!Y2:Y39, NOT(ISNUMBER(SEARCH(""Retirée"", 'Feuille "&"1'!A2:A39)))), FALSE), 4)"),6.0) -> 6 | S5: ⚠️ Danger fantôme | T5: =COUNTIF('Feuille 1'!AA2:AA39, "⚠️ Danger fantôme") -> 11
P6: =IFERROR(__xludf.DUMMYFUNCTION("INDEX(SORT(FILTER('Feuille 1'!A2:A39, NOT(ISNUMBER(SEARCH(""Retirée"", 'Feuille 1'!A2:A39)))), FILTER('Feuille 1'!Z2:Z39, NOT(ISNUMBER(SEARCH(""Retirée"", 'Feuille 1'!A2:A39)))), FALSE, FILTER('Feuille 1'!Y2:Y39, NOT(ISNUMBER(SEARCH(""Retirée"", 'Feuille "&"1'!A2:A39)))), FALSE), 5)"),"imRqin") -> imRqin | Q6: =IFERROR(__xludf.DUMMYFUNCTION("INDEX(SORT(FILTER('Feuille 1'!Z2:Z39, NOT(ISNUMBER(SEARCH(""Retirée"", 'Feuille 1'!A2:A39)))), FILTER('Feuille 1'!Z2:Z39, NOT(ISNUMBER(SEARCH(""Retirée"", 'Feuille 1'!A2:A39)))), FALSE, FILTER('Feuille 1'!Y2:Y39, NOT(ISNUMBER(SEARCH(""Retirée"", 'Feuille "&"1'!A2:A39)))), FALSE), 5)"),6.0) -> 6
B7: 👤 PROFIL INDIVIDUEL DU MODÉRATEUR | I7: ⚡ FILTRE PAR GRADE & VUE DYNAMIQUE (38 MODÉRATEURS) | P7: =IFERROR(__xludf.DUMMYFUNCTION("INDEX(SORT(FILTER('Feuille 1'!A2:A39, NOT(ISNUMBER(SEARCH(""Retirée"", 'Feuille 1'!A2:A39)))), FILTER('Feuille 1'!Z2:Z39, NOT(ISNUMBER(SEARCH(""Retirée"", 'Feuille 1'!A2:A39)))), FALSE, FILTER('Feuille 1'!Y2:Y39, NOT(ISNUMBER(SEARCH(""Retirée"", 'Feuille "&"1'!A2:A39)))), FALSE), 6)"),"Sako76_") -> Sako76_ | Q7: =IFERROR(__xludf.DUMMYFUNCTION("INDEX(SORT(FILTER('Feuille 1'!Z2:Z39, NOT(ISNUMBER(SEARCH(""Retirée"", 'Feuille 1'!A2:A39)))), FILTER('Feuille 1'!Z2:Z39, NOT(ISNUMBER(SEARCH(""Retirée"", 'Feuille 1'!A2:A39)))), FALSE, FILTER('Feuille 1'!Y2:Y39, NOT(ISNUMBER(SEARCH(""Retirée"", 'Feuille "&"1'!A2:A39)))), FALSE), 6)"),4.0) -> 4
B8: Sélection : | C8: amandinee_22 | I8: TOUS | K8: =IF(I8="TOUS", (COUNTA('Feuille 1'!A2:A39)-COUNTIF('Feuille 1'!A2:A39, "*Retirée*")) & " modérateurs", COUNTIF('Feuille 1'!AA2:AA39, I8) & " modérateur(s)") -> 37 modérateurs | P8: =IFERROR(__xludf.DUMMYFUNCTION("INDEX(SORT(FILTER('Feuille 1'!A2:A39, NOT(ISNUMBER(SEARCH(""Retirée"", 'Feuille 1'!A2:A39)))), FILTER('Feuille 1'!Z2:Z39, NOT(ISNUMBER(SEARCH(""Retirée"", 'Feuille 1'!A2:A39)))), FALSE, FILTER('Feuille 1'!Y2:Y39, NOT(ISNUMBER(SEARCH(""Retirée"", 'Feuille "&"1'!A2:A39)))), FALSE), 7)"),"amandinee_22") -> amandinee_22 | Q8: =IFERROR(__xludf.DUMMYFUNCTION("INDEX(SORT(FILTER('Feuille 1'!Z2:Z39, NOT(ISNUMBER(SEARCH(""Retirée"", 'Feuille 1'!A2:A39)))), FILTER('Feuille 1'!Z2:Z39, NOT(ISNUMBER(SEARCH(""Retirée"", 'Feuille 1'!A2:A39)))), FALSE, FILTER('Feuille 1'!Y2:Y39, NOT(ISNUMBER(SEARCH(""Retirée"", 'Feuille "&"1'!A2:A39)))), FALSE), 7)"),4.0) -> 4
B9: Grade actuel : | D9: =IFERROR(VLOOKUP(C8, 'Feuille 1'!A2:AC39, 27, FALSE), "-") -> ⭐ Modo Actif | P9: =IFERROR(__xludf.DUMMYFUNCTION("INDEX(SORT(FILTER('Feuille 1'!A2:A39, NOT(ISNUMBER(SEARCH(""Retirée"", 'Feuille 1'!A2:A39)))), FILTER('Feuille 1'!Z2:Z39, NOT(ISNUMBER(SEARCH(""Retirée"", 'Feuille 1'!A2:A39)))), FALSE, FILTER('Feuille 1'!Y2:Y39, NOT(ISNUMBER(SEARCH(""Retirée"", 'Feuille "&"1'!A2:A39)))), FALSE), 8)"),"Xdayman") -> Xdayman | Q9: =IFERROR(__xludf.DUMMYFUNCTION("INDEX(SORT(FILTER('Feuille 1'!Z2:Z39, NOT(ISNUMBER(SEARCH(""Retirée"", 'Feuille 1'!A2:A39)))), FILTER('Feuille 1'!Z2:Z39, NOT(ISNUMBER(SEARCH(""Retirée"", 'Feuille 1'!A2:A39)))), FALSE, FILTER('Feuille 1'!Y2:Y39, NOT(ISNUMBER(SEARCH(""Retirée"", 'Feuille "&"1'!A2:A39)))), FALSE), 8)"),4.0) -> 4
B10: Statut / Rôle : | D10: =IFERROR(VLOOKUP(C8, 'Feuille 1'!A2:AC39, 29, FALSE), "-") -> Très actif | I10: Modérateur | J10: Grade | K10: Score (J15-J16) | L10: Assiduité | M10: Sessions (+) | N10: Statut / Rôle
B11: Score Global : | D11: =IFERROR(VLOOKUP(C8, 'Feuille 1'!A2:AC39, 26, FALSE), 0) -> 4 | E11: Taux d'assiduité : | G11: =IFERROR(VLOOKUP(C8, 'Feuille 1'!A2:AC39, 25, FALSE), 0) -> 1 | I11: =IFERROR(__xludf.DUMMYFUNCTION("IFERROR(SORT(CHOOSECOLS(FILTER('Feuille 1'!A2:AC39, IF(I8=""TOUS"", NOT(ISNUMBER(SEARCH(""Retirée"", 'Feuille 1'!A2:A39))), 'Feuille 1'!AA2:AA39=I8)), 1, 27, 26, 25, 24, 29), 3, FALSE, 4, FALSE), ""Aucun résultat"")"),"AyssAFK") -> AyssAFK | J11: =IFERROR(__xludf.DUMMYFUNCTION("""COMPUTED_VALUE"""),"👑 Top Modo") -> 👑 Top Modo | K11: =IFERROR(__xludf.DUMMYFUNCTION("""COMPUTED_VALUE"""),6.0) -> 6 | L11: =IFERROR(__xludf.DUMMYFUNCTION("""COMPUTED_VALUE"""),1.0) -> 1 | M11: =IFERROR(__xludf.DUMMYFUNCTION("""COMPUTED_VALUE"""),2.0) -> 2 | N11: =IFERROR(__xludf.DUMMYFUNCTION("""COMPUTED_VALUE"""),"Actif") -> Actif
B12: 📊 RÉPARTITION DÉTAILLÉE DES SESSIONS (PÉRIODE ACTIVE J15-J16) | I12: =IFERROR(__xludf.DUMMYFUNCTION("""COMPUTED_VALUE"""),"jawad_4k") -> jawad_4k | J12: =IFERROR(__xludf.DUMMYFUNCTION("""COMPUTED_VALUE"""),"👑 Top Modo") -> 👑 Top Modo | K12: =IFERROR(__xludf.DUMMYFUNCTION("""COMPUTED_VALUE"""),6.0) -> 6 | L12: =IFERROR(__xludf.DUMMYFUNCTION("""COMPUTED_VALUE"""),1.0) -> 1 | M12: =IFERROR(__xludf.DUMMYFUNCTION("""COMPUTED_VALUE"""),2.0) -> 2 | N12: =IFERROR(__xludf.DUMMYFUNCTION("""COMPUTED_VALUE"""),"Actif") -> Actif
B13: 🟢 Active beaucoup | C13: 🟡 Active un peu | D13: 🔵 Abs. justifiée | E13: 🔴 Pas là | F13: ⚡ Présence active | I13: =IFERROR(__xludf.DUMMYFUNCTION("""COMPUTED_VALUE"""),"uf_th3_dreamzz") -> uf_th3_dreamzz | J13: =IFERROR(__xludf.DUMMYFUNCTION("""COMPUTED_VALUE"""),"👑 Top Modo") -> 👑 Top Modo | K13: =IFERROR(__xludf.DUMMYFUNCTION("""COMPUTED_VALUE"""),6.0) -> 6 | L13: =IFERROR(__xludf.DUMMYFUNCTION("""COMPUTED_VALUE"""),1.0) -> 1 | M13: =IFERROR(__xludf.DUMMYFUNCTION("""COMPUTED_VALUE"""),2.0) -> 2 | N13: =IFERROR(__xludf.DUMMYFUNCTION("""COMPUTED_VALUE"""),"Actif") -> Actif
B14: =IFERROR(VLOOKUP(C8, 'Feuille 1'!A2:AC39, 24, FALSE), 0) -> 1 | C14: =IFERROR(VLOOKUP(C8, 'Feuille 1'!A2:AC39, 23, FALSE), 0) -> 1 | D14: =IFERROR(VLOOKUP(C8, 'Feuille 1'!A2:AC39, 22, FALSE), 0) -> 0 | E14: =IFERROR(VLOOKUP(C8, 'Feuille 1'!A2:AC39, 21, FALSE), 0) -> 0 | F14: =IFERROR((B14+C14) & " j actifs / 2 j", "-") -> 2 j actifs / 2 j | I14: =IFERROR(__xludf.DUMMYFUNCTION("""COMPUTED_VALUE"""),"nini_nesss") -> nini_nesss | J14: =IFERROR(__xludf.DUMMYFUNCTION("""COMPUTED_VALUE"""),"👑 Top Modo") -> 👑 Top Modo | K14: =IFERROR(__xludf.DUMMYFUNCTION("""COMPUTED_VALUE"""),6.0) -> 6 | L14: =IFERROR(__xludf.DUMMYFUNCTION("""COMPUTED_VALUE"""),1.0) -> 1 | M14: =IFERROR(__xludf.DUMMYFUNCTION("""COMPUTED_VALUE"""),2.0) -> 2 | N14: =IFERROR(__xludf.DUMMYFUNCTION("""COMPUTED_VALUE"""),"Actif") -> Actif
B15: Jauge assiduité : | C15: =IFERROR(__xludf.DUMMYFUNCTION("IFERROR(SPARKLINE(G11, {""charttype"",""bar""; ""max"",1; ""color1"",IF(G11>=0.75, ""#16A34A"", IF(G11>=0.4, ""#EAB308"", ""#DC2626""))}), """")"),"") | I15: =IFERROR(__xludf.DUMMYFUNCTION("""COMPUTED_VALUE"""),"imRqin") -> imRqin | J15: =IFERROR(__xludf.DUMMYFUNCTION("""COMPUTED_VALUE"""),"👑 Top Modo") -> 👑 Top Modo | K15: =IFERROR(__xludf.DUMMYFUNCTION("""COMPUTED_VALUE"""),6.0) -> 6 | L15: =IFERROR(__xludf.DUMMYFUNCTION("""COMPUTED_VALUE"""),1.0) -> 1 | M15: =IFERROR(__xludf.DUMMYFUNCTION("""COMPUTED_VALUE"""),2.0) -> 2 | N15: =IFERROR(__xludf.DUMMYFUNCTION("""COMPUTED_VALUE"""),"Actif") -> Actif
B16: =IFERROR(__xludf.DUMMYFUNCTION("SPARKLINE(MAP('Feuille 1'!E1:F1, LAMBDA(j, SWITCH(INDEX('Feuille 1'!E2:F39, MATCH(C8, 'Feuille 1'!A2:A39, 0), COLUMN(j)-4), ""Active beaucoup"", 2, ""Active un peu"", 1, ""Absence justifiée"", 0, ""Pas là"", -1, 0))), {""charttype"",""column""; ""color"","&"""#2563EB""; ""negcolor"",""#EF4444""; ""ymin"",-1; ""ymax"",2})"),"") | C16: =IFERROR(__xludf.DUMMYFUNCTION("SPARKLINE(MAP('Feuille 1'!E1:G1, LAMBDA(j, SWITCH(INDEX('Feuille 1'!E2:G39, MATCH(C8, 'Feuille 1'!A2:A39, 0), COLUMN(j)-4), ""Active beaucoup"", 2, ""Active un peu"", 1, ""Absence justifiée"", 0, ""Pas là"", -1, 0))), {""charttype"",""column""; ""color"","&"""#2563EB""; ""negcolor"",""#EF4444""; ""ymin"",-1; ""ymax"",2})"),"") | I16: =IFERROR(__xludf.DUMMYFUNCTION("""COMPUTED_VALUE"""),"Sako76_") -> Sako76_ | J16: =IFERROR(__xludf.DUMMYFUNCTION("""COMPUTED_VALUE"""),"⭐ Modo Actif") -> ⭐ Modo Actif | K16: =IFERROR(__xludf.DUMMYFUNCTION("""COMPUTED_VALUE"""),4.0) -> 4 | L16: =IFERROR(__xludf.DUMMYFUNCTION("""COMPUTED_VALUE"""),1.0) -> 1 | M16: =IFERROR(__xludf.DUMMYFUNCTION("""COMPUTED_VALUE"""),1.0) -> 1 | N16: =IFERROR(__xludf.DUMMYFUNCTION("""COMPUTED_VALUE"""),"En observation") -> En observation
B17: ⚔️ ACTIONS DE MODÉRATION RÉELLES (J15 - J16) | I17: =IFERROR(__xludf.DUMMYFUNCTION("""COMPUTED_VALUE"""),"amandinee_22") -> amandinee_22 | J17: =IFERROR(__xludf.DUMMYFUNCTION("""COMPUTED_VALUE"""),"⭐ Modo Actif") -> ⭐ Modo Actif | K17: =IFERROR(__xludf.DUMMYFUNCTION("""COMPUTED_VALUE"""),4.0) -> 4 | L17: =IFERROR(__xludf.DUMMYFUNCTION("""COMPUTED_VALUE"""),1.0) -> 1 | M17: =IFERROR(__xludf.DUMMYFUNCTION("""COMPUTED_VALUE"""),1.0) -> 1 | N17: =IFERROR(__xludf.DUMMYFUNCTION("""COMPUTED_VALUE"""),"Très actif") -> Très actif
B18: Total Actions : | D18: =IFERROR(VLOOKUP(C8, 'Actions Modération'!A6:G43, 5, FALSE), 0) -> 23 | E18: Moyenne / Jour : | G18: =IFERROR(VLOOKUP(C8, 'Actions Modération'!A6:G43, 6, FALSE), 0) -> 11.5 | I18: =IFERROR(__xludf.DUMMYFUNCTION("""COMPUTED_VALUE"""),"Xdayman") -> Xdayman | J18: =IFERROR(__xludf.DUMMYFUNCTION("""COMPUTED_VALUE"""),"⭐ Modo Actif") -> ⭐ Modo Actif | K18: =IFERROR(__xludf.DUMMYFUNCTION("""COMPUTED_VALUE"""),4.0) -> 4 | L18: =IFERROR(__xludf.DUMMYFUNCTION("""COMPUTED_VALUE"""),1.0) -> 1 | M18: =IFERROR(__xludf.DUMMYFUNCTION("""COMPUTED_VALUE"""),1.0) -> 1 | N18: =IFERROR(__xludf.DUMMYFUNCTION("""COMPUTED_VALUE"""),"Actif") -> Actif
B19: Jour 15 (04/10) | C19: Jour 16 (05/10) | D19: Jour 17 (06/10) | E19: Total Cumulé | I19: =IFERROR(__xludf.DUMMYFUNCTION("""COMPUTED_VALUE"""),"Su_wii") -> Su_wii | J19: =IFERROR(__xludf.DUMMYFUNCTION("""COMPUTED_VALUE"""),"⭐ Modo Actif") -> ⭐ Modo Actif | K19: =IFERROR(__xludf.DUMMYFUNCTION("""COMPUTED_VALUE"""),4.0) -> 4 | L19: =IFERROR(__xludf.DUMMYFUNCTION("""COMPUTED_VALUE"""),1.0) -> 1 | M19: =IFERROR(__xludf.DUMMYFUNCTION("""COMPUTED_VALUE"""),1.0) -> 1 | N19: =IFERROR(__xludf.DUMMYFUNCTION("""COMPUTED_VALUE"""),"Peu actif") -> Peu actif
B20: =IFERROR(VLOOKUP(C8, 'Actions Modération'!A6:G43, 2, FALSE), 0) -> 4 | C20: =IFERROR(VLOOKUP(C8, 'Actions Modération'!A6:G43, 3, FALSE), 0) -> 19 | D20: =IFERROR(VLOOKUP(C8, 'Actions Modération'!A6:G43, 4, FALSE), 0) -> 0 | E20: =D18 -> 23 | I20: =IFERROR(__xludf.DUMMYFUNCTION("""COMPUTED_VALUE"""),"naxoo_of") -> naxoo_of | J20: =IFERROR(__xludf.DUMMYFUNCTION("""COMPUTED_VALUE"""),"⭐ Modo Actif") -> ⭐ Modo Actif | K20: =IFERROR(__xludf.DUMMYFUNCTION("""COMPUTED_VALUE"""),4.0) -> 4 | L20: =IFERROR(__xludf.DUMMYFUNCTION("""COMPUTED_VALUE"""),1.0) -> 1 | M20: =IFERROR(__xludf.DUMMYFUNCTION("""COMPUTED_VALUE"""),1.0) -> 1 | N20: =IFERROR(__xludf.DUMMYFUNCTION("""COMPUTED_VALUE"""),"Actif") -> Actif
B21: =IFERROR(__xludf.DUMMYFUNCTION("IF(D18=0, ""Aucune action enregistrée sur J15-J16"", SPARKLINE(B20:C20, {""charttype"",""column"";""color"",""#3B82F6""}))"),"") | C21: =IFERROR(__xludf.DUMMYFUNCTION("IF(D18=0, ""Aucune action enregistrée sur J15-J17"", SPARKLINE(B20:D20, {""charttype"",""column"";""color"",""#3B82F6""}))"),"") | I21: =IFERROR(__xludf.DUMMYFUNCTION("""COMPUTED_VALUE"""),"eren835_") -> eren835_ | J21: =IFERROR(__xludf.DUMMYFUNCTION("""COMPUTED_VALUE"""),"⭐ Modo Actif") -> ⭐ Modo Actif | K21: =IFERROR(__xludf.DUMMYFUNCTION("""COMPUTED_VALUE"""),4.0) -> 4 | L21: =IFERROR(__xludf.DUMMYFUNCTION("""COMPUTED_VALUE"""),1.0) -> 1 | M21: =IFERROR(__xludf.DUMMYFUNCTION("""COMPUTED_VALUE"""),1.0) -> 1 | N21: =IFERROR(__xludf.DUMMYFUNCTION("""COMPUTED_VALUE"""),"En observation") -> En observation
B22: 🎯 OBJECTIFS & ATTEINTE DE CIBLE HEBDO | I22: =IFERROR(__xludf.DUMMYFUNCTION("""COMPUTED_VALUE"""),"moonstoness__") -> moonstoness__ | J22: =IFERROR(__xludf.DUMMYFUNCTION("""COMPUTED_VALUE"""),"⭐ Modo Actif") -> ⭐ Modo Actif | K22: =IFERROR(__xludf.DUMMYFUNCTION("""COMPUTED_VALUE"""),3.0) -> 3 | L22: =IFERROR(__xludf.DUMMYFUNCTION("""COMPUTED_VALUE"""),1.0) -> 1 | M22: =IFERROR(__xludf.DUMMYFUNCTION("""COMPUTED_VALUE"""),1.0) -> 1 | N22: =IFERROR(__xludf.DUMMYFUNCTION("""COMPUTED_VALUE"""),"Très actif") -> Très actif
B23: Cible Hebdomadaire : | D23: 200 | E23: Actions 7j (estimées) : | G23: =IFERROR(ROUND(G18*7, 0), 0) -> 81 | I23: =IFERROR(__xludf.DUMMYFUNCTION("""COMPUTED_VALUE"""),"ssbk691") -> ssbk691 | J23: =IFERROR(__xludf.DUMMYFUNCTION("""COMPUTED_VALUE"""),"🔎 En observation") -> 🔎 En observation | K23: =IFERROR(__xludf.DUMMYFUNCTION("""COMPUTED_VALUE"""),2.0) -> 2 | L23: =IFERROR(__xludf.DUMMYFUNCTION("""COMPUTED_VALUE"""),1.0) -> 1 | M23: =IFERROR(__xludf.DUMMYFUNCTION("""COMPUTED_VALUE"""),0.0) -> 0 | N23: =IFERROR(__xludf.DUMMYFUNCTION("""COMPUTED_VALUE"""),"Actif") -> Actif
